<robot name="mastcam">

  <link name="base_link">
    <visual>
      <origin xyz="0 0 0" rpy="0 0 0"/>
      <geometry>
        <mesh filename="package://ag_mastcam/meshes/link_1.stl" scale="0.001 0.001 0.001"/>
      </geometry>
      <material name="Grey">
        <color rgba="0.9 0.9 0.8 1.0"/>
      </material>
    </visual>
  </link>
  
  <link name="link_1">
    <visual>
      <origin xyz="0 0 -0.049" rpy="0 0 3.14159"/>
      <geometry>
        <mesh filename="package://ag_mastcam/meshes/link_2.stl" scale="0.001 0.001 0.001"/>
      </geometry>
      <material name="Grey">
        <color rgba="0.9 0.9 0.8 1.0"/>
      </material>
    </visual>
  </link>

  <link name="link_2">
    <visual>
      <origin xyz="0 -0.0716 0" rpy="0 1.5708 1.5708"/>
      <geometry>
        <mesh filename="package://ag_mastcam/meshes/link_3.stl" scale="0.001 0.001 0.001"/>
      </geometry>
      <material name="Grey">
        <color rgba="0.9 0.9 0.8 1.0"/>
      </material>
    </visual>
  </link>

  <link name="camera_link">
    <visual>
      <origin xyz="0.0 0.0 0.0" rpy="0.0 0.0 0.0"/>
      <geometry>
        <cylinder radius="0.01" length="0.025"/>
      </geometry>  
    </visual>
  </link>


  <joint name="pan_joint" type="revolute">
    <parent link="base_link"/>
    <child link="link_1"/>
    <origin xyz="0 0 0.049" rpy="0 0 0"/>
    <axis xyz="0 0 1"/>

    <!-- Joint limits -->
    <limit lower="1.5708" upper="4.7124" velocity="11.5" effort="100"/>
    <!-- Soft limits -->
    <safety_controller k_position="3"
                    k_velocity="1000"
                    soft_lower_limit="-10.1415"
                    soft_upper_limit="10.1415" />
  </joint>

  <joint name="tilt_joint" type="revolute">
    <parent link="link_1"/>
    <child link="link_2"/>
    <origin xyz="0 0 0.0226" rpy="-1.5708 0 -1.5708"/>
    <axis xyz="0 0 1"/>

    <!-- Joint limits -->
    <limit lower="1.5708" upper="4.7124" velocity="11.5" effort="100"/>
    <!-- Soft limits -->
    <safety_controller k_position="3"
                    k_velocity="1000"
                    soft_lower_limit="-10.1415"
                    soft_upper_limit="10.1415" />
  </joint>

  <joint name="camera_joint" type="fixed">
    <parent link="link_2"/>
    <child link="camera_link"/>
    <origin xyz="0 0.056 0" rpy="3.14159 1.5708 0"/>
  </joint>
 
</robot>
